Workbook

Sheet POA2026_ej
A1: Resultado_cod | B1: Resultado | C1: Producto_cod | D1: Producto | E1: Tipo_producto_cod | F1: Tipo de producto | G1: Nivel | H1: Entidad_p6 | I1: Actividad_cod | J1: Actividad_name | K1: Actividad | L1: Indicador | M1: Unidad de medida | N1: Medio de verificación | O1: Logro Esperado | P1: ene_pl | Q1: feb_pl | R1: mar_pl | S1: abr_pl | T1: may_pl | U1: jun_pl | V1: jul_pl | W1: ago_pl | X1: set_pl | Y1: oct_pl | Z1: nov_pl | AA1: dic_pl | AB1: Pl_total | AC1: ene_ej | AD1: feb_ej | AE1: mar_ej | AF1: abr_ej | AG1: may_ej | AH1: jun_ej | AI1: jul_ej | AJ1: ago_ej | AK1: set_ej | AL1: oct_ej | AM1: nov_ej | AN1: dic_ej | AO1: Ej_total
A2: D1 | B2: =IFERROR(CONCATENATE(A2,". ",VLOOKUP(A2,'results, prods y acts'!$A$2:$B$8,2,FALSE)),"") -> D1. Los procesos estratégicos y de soporte se realizan de forma eficaz y eficiente | C2: D1.1 | D2: =IFERROR(CONCATENATE(C2,". ",VLOOKUP(C2,'results, prods y acts'!$D$2:$E$12,2,FALSE)),CONCATENATE(C2,". ")) -> D1.1. Informes semestrales | I2: D1.1.1 | J2: Envío a SECO | K2: =CONCATENATE(I2,". ",J2) -> D1.1.1. Envío a SECO | L2: Número de informes | M2: Informe | N2: Correo de envío | O2: Informes enviados en el tiempo esperado | Q2: 1 | W2: 1 | AB2: =SUM(P2:AA2) -> 2
A3: D1 | B3: =IFERROR(CONCATENATE(A3,". ",VLOOKUP(A3,'results, prods y acts'!$A$2:$B$8,2,FALSE)),"") -> D1. Los procesos estratégicos y de soporte se realizan de forma eficaz y eficiente | C3: D1.1 | D3: =IFERROR(CONCATENATE(C3,". ",VLOOKUP(C3,'results, prods y acts'!$D$2:$E$12,2,FALSE)),CONCATENATE(C3,". ")) -> D1.1. Informes semestrales | I3: D1.1.2 | J3: Absolución de comentarios | K3: =CONCATENATE(I3,". ",J3) -> D1.1.2. Absolución de comentarios | L3: Número de respuestas | M3: Informe | N3: Correo de envío | O3: Informes enviados en el tiempo esperado | Q3: 1 | W3: 1 | AB3: =SUM(P3:AA3) -> 2
A4: D1 | B4: =IFERROR(CONCATENATE(A4,". ",VLOOKUP(A4,'results, prods y acts'!$A$2:$B$8,2,FALSE)),"") -> D1. Los procesos estratégicos y de soporte se realizan de forma eficaz y eficiente | C4: D1.2 | D4: =IFERROR(CONCATENATE(C4,". ",VLOOKUP(C4,'results, prods y acts'!$D$2:$E$12,2,FALSE)),CONCATENATE(C4,". ")) -> D1.2. Planificación Operativa | I4: D1.2.1 | J4: Reuniones de trabajo con el equipo del Programa para el diseño y aprobación del POA | K4: =CONCATENATE(I4,". ",J4) -> D1.2.1. Reuniones de trabajo con el equipo del Programa para el diseño y aprobación del POA | L4: Número de planes | M4: Plan | N4: Correo de envío | O4: Plan aprobado | AA4: 1 | AB4: =SUM(P4:AA4) -> 1
A5: D1 | B5: =IFERROR(CONCATENATE(A5,". ",VLOOKUP(A5,'results, prods y acts'!$A$2:$B$8,2,FALSE)),"") -> D1. Los procesos estratégicos y de soporte se realizan de forma eficaz y eficiente | C5: D1.3 | D5: =IFERROR(CONCATENATE(C5,". ",VLOOKUP(C5,'results, prods y acts'!$D$2:$E$12,2,FALSE)),CONCATENATE(C5,". ")) -> D1.3. Monitoreo y Evaluación | I5: D1.3.1 | J5: Reuniones mensuales de seguimiento | K5: =CONCATENATE(I5,". ",J5) -> D1.3.1. Reuniones mensuales de seguimiento | L5: Número de reuniones | M5: Reuniones | N5: Acta de reunión | O5: Las áreas encuentran puntos de mejora para el desarrollo de estrategias para la consecución de sus objetivos. | P5: 1 | Q5: 1 | R5: 1 | S5: 1 | T5: 1 | U5: 1 | V5: 1 | W5: 1 | X5: 1 | Y5: 1 | Z5: 1 | AA5: 1 | AB5: =SUM(P5:AA5) -> 12
A6: D1 | B6: =IFERROR(CONCATENATE(A6,". ",VLOOKUP(A6,'results, prods y acts'!$A$2:$B$8,2,FALSE)),"") -> D1. Los procesos estratégicos y de soporte se realizan de forma eficaz y eficiente | C6: D1.3 | D6: =IFERROR(CONCATENATE(C6,". ",VLOOKUP(C6,'results, prods y acts'!$D$2:$E$12,2,FALSE)),CONCATENATE(C6,". ")) -> D1.3. Monitoreo y Evaluación | I6: D1.3.2 | J6: Reuniones de identificación y gestión de riesgos | K6: =CONCATENATE(I6,". ",J6) -> D1.3.2. Reuniones de identificación y gestión de riesgos | L6: Número de reuniones | M6: Reuniones | N6: Acta de reunión | O6: Se analizan posibles riesgos y, de requerirse, se establecen medidas para su mitigación | Q6: 1 | W6: 1 | AB6: =SUM(P6:AA6) -> 2
A7: D1 | B7: =IFERROR(CONCATENATE(A7,". ",VLOOKUP(A7,'results, prods y acts'!$A$2:$B$8,2,FALSE)),"") -> D1. Los procesos estratégicos y de soporte se realizan de forma eficaz y eficiente | C7: D1.4 | D7: =IFERROR(CONCATENATE(C7,". ",VLOOKUP(C7,'results, prods y acts'!$D$2:$E$12,2,FALSE)),CONCATENATE(C7,". ")) -> D1.4. Coordinación con socios, cooperantes y Programas de SECO | I7: D1.4.1 | J7: Espacios de incidencia política | K7: =CONCATENATE(I7,". ",J7) -> D1.4.1. Espacios de incidencia política | L7: Número de reuniones | M7: Reuniones | N7: Acta de reunión | O7: Se recogen retroalimentación del MEF | U7: 1 | AA7: 1 | AB7: =SUM(P7:AA7) -> 2
A8: D1 | B8: =IFERROR(CONCATENATE(A8,". ",VLOOKUP(A8,'results, prods y acts'!$A$2:$B$8,2,FALSE)),"") -> D1. Los procesos estratégicos y de soporte se realizan de forma eficaz y eficiente | C8: D1.4 | D8: =IFERROR(CONCATENATE(C8,". ",VLOOKUP(C8,'results, prods y acts'!$D$2:$E$12,2,FALSE)),CONCATENATE(C8,". ")) -> D1.4. Coordinación con socios, cooperantes y Programas de SECO | I8: D1.4.2 | J8: Reuniones del Comité de Piloteo con SECO y Basel Institute sede Suiza | K8: =CONCATENATE(I8,". ",J8) -> D1.4.2. Reuniones del Comité de Piloteo con SECO y Basel Institute sede Suiza | L8: Número de reuniones | M8: Reuniones | N8: Acta de reunión | O8: Se recoge retroalimentación para la implementación del Programa | V8: 1 | Y8: 1 | AB8: =SUM(P8:AA8) -> 2
A9: D1 | B9: =IFERROR(CONCATENATE(A9,". ",VLOOKUP(A9,'results, prods y acts'!$A$2:$B$8,2,FALSE)),"") -> D1. Los procesos estratégicos y de soporte se realizan de forma eficaz y eficiente | C9: D1.4 | D9: =IFERROR(CONCATENATE(C9,". ",VLOOKUP(C9,'results, prods y acts'!$D$2:$E$12,2,FALSE)),CONCATENATE(C9,". ")) -> D1.4. Coordinación con socios, cooperantes y Programas de SECO | I9: D1.4.3 | J9: Difusión de Asistencias Técnicas R1,R2,R3,R4, R5 | K9: =CONCATENATE(I9,". ",J9) -> D1.4.3. Difusión de Asistencias Técnicas R1,R2,R3,R4, R5 | L9: Número de herramientas o eventos de difusión elaborados en el mes sobre Asistencias Técnicas realizadas. | M9: Informe | N9: Documento | O9: Se difunden avances de resultados del Programa y se cumplen al 100% los resultados previstos por la Dirección (Buenos resultados en entrevistas con Autoridades, en ratificación de Planes de acción y en Interaacción con otros Programas de SECO) | P9: 1 | Q9: 1 | R9: 1 | S9: 1 | T9: 1 | U9: 1 | V9: 1 | W9: 1 | X9: 1 | Y9: 1 | Z9: 1 | AA9: 1 | AB9: =SUM(P9:AA9) -> 12
A10: D1 | B10: =IFERROR(CONCATENATE(A10,". ",VLOOKUP(A10,'results, prods y acts'!$A$2:$B$8,2,FALSE)),"") -> D1. Los procesos estratégicos y de soporte se realizan de forma eficaz y eficiente | C10: D1.4 | D10: =IFERROR(CONCATENATE(C10,". ",VLOOKUP(C10,'results, prods y acts'!$D$2:$E$12,2,FALSE)),CONCATENATE(C10,". ")) -> D1.4. Coordinación con socios, cooperantes y Programas de SECO | I10: D1.4.4 | J10: Difusión de Capacitaciones/Fortalecimiento de Capacidades realizados por R1, R2,R3,R4,R5 | K10: =CONCATENATE(I10,". ",J10) -> D1.4.4. Difusión de Capacitaciones/Fortalecimiento de Capacidades realizados por R1, R2,R3,R4,R5 | L10: Número de herramientas o eventos de difusión elaboradas/ desarrolladas en el mes sobre Capacitaciones/ Fortalecimiento de Capacidades realizadas | M10: Informe | N10: Documento | O10: Se difunden avances de resultados del Programa y se cumplen al 100% los resultados previstos por la Dirección (Buenos resultados en entrevistas con Autoridades, en ratificación de Planes de acción y en Interaacción con Programas de SECO) | S10: 1 | V10: 1 | W10: 1 | AB10: =SUM(P10:AA10) -> 3
A11: D1 | B11: =IFERROR(CONCATENATE(A11,". ",VLOOKUP(A11,'results, prods y acts'!$A$2:$B$8,2,FALSE)),"") -> D1. Los procesos estratégicos y de soporte se realizan de forma eficaz y eficiente | C11: D1.4 | D11: =IFERROR(CONCATENATE(C11,". ",VLOOKUP(C11,'results, prods y acts'!$D$2:$E$12,2,FALSE)),CONCATENATE(C11,". ")) -> D1.4. Coordinación con socios, cooperantes y Programas de SECO | I11: D1.4.5 | J11: Difusión de Instrumentos de Mejora de la Gestión realizados por el Programa (R1,R2,R3,R4,R5) | K11: =CONCATENATE(I11,". ",J11) -> D1.4.5. Difusión de Instrumentos de Mejora de la Gestión realizados por el Programa (R1,R2,R3,R4,R5) | L11: Número de herramientas o eventos de difusión elaboradas/ desarrolladas en el mes sobre Capacitaciones/ Fortalecimiento de Capacidades realizadas | M11: Informe | N11: Documento | O11: Se difunden avances de resultados del Programa y se cumplen al 100% los resultados previstos por la Dirección (Buenos resultados en entrevistas con Autoridades, en ratificación de Planes de acción y en Interaacción con otros Programas de SECO) | V11: 1 | AB11: =SUM(P11:AA11) -> 1
A12: D1 | B12: =IFERROR(CONCATENATE(A12,". ",VLOOKUP(A12,'results, prods y acts'!$A$2:$B$8,2,FALSE)),"") -> D1. Los procesos estratégicos y de soporte se realizan de forma eficaz y eficiente | C12: D1.4 | D12: =IFERROR(CONCATENATE(C12,". ",VLOOKUP(C12,'results, prods y acts'!$D$2:$E$12,2,FALSE)),CONCATENATE(C12,". ")) -> D1.4. Coordinación con socios, cooperantes y Programas de SECO | I12: D1.4.7 | J12: Visitas técnicas a los GSN (GR y MP) | K12: =CONCATENATE(I12,". ",J12) -> D1.4.7. Visitas técnicas a los GSN (GR y MP) | L12: Número de visitas técnicas | M12: Reunión | N12: Reporte | O12: Las autoridades de los GSN se preparan para el cierre de gestión 2023-2026 | P12: 1 | Q12: 1 | R12: 1 | S12: 1 | T12: 1 | U12: 1 | V12: 1 | W12: 1 | X12: 1 | Y12: 1 | Z12: 1 | AA12: 1 | AB12: =SUM(P12:AA12) -> 12
A13: D1 | B13: =IFERROR(CONCATENATE(A13,". ",VLOOKUP(A13,'results, prods y acts'!$A$2:$B$8,2,FALSE)),"") -> D1. Los procesos estratégicos y de soporte se realizan de forma eficaz y eficiente | C13: D1.4 | D13: =IFERROR(CONCATENATE(C13,". ",VLOOKUP(C13,'results, prods y acts'!$D$2:$E$12,2,FALSE)),CONCATENATE(C13,". ")) -> D1.4. Coordinación con socios, cooperantes y Programas de SECO | I13: D1.4.6 | J13: Reuniones de coordinación con gerentes clave (Planeamiento y Presupuesto) de los GR | K13: =CONCATENATE(I13,". ",J13) -> D1.4.6. Reuniones de coordinación con gerentes clave (Planeamiento y Presupuesto) de los GR | L13: Número de reuniones de coordinación con autoridades de los GR | M13: Reunión | N13: Reporte | O13: Se brinda acompañamiento técnico a las autoridades de los GSN en el proceso de transición hacia el nuevo periodo de gobierno, en el contexto de las elecciones generales 2026 | P13: 1 | Q13: 1 | R13: 1 | S13: 1 | T13: 1 | U13: 1 | AB13: =SUM(P13:AA13) -> 6
A14: D1 | B14: =IFERROR(CONCATENATE(A14,". ",VLOOKUP(A14,'results, prods y acts'!$A$2:$B$8,2,FALSE)),"") -> D1. Los procesos estratégicos y de soporte se realizan de forma eficaz y eficiente | C14: D1.4 | D14: =IFERROR(CONCATENATE(C14,". ",VLOOKUP(C14,'results, prods y acts'!$D$2:$E$12,2,FALSE)),CONCATENATE(C14,". ")) -> D1.4. Coordinación con socios, cooperantes y Programas de SECO | I14: D1.4.8 | J14: Reuniones estratégicas con candidatos a autoridades subnacionales | K14: =CONCATENATE(I14,". ",J14) -> D1.4.8. Reuniones estratégicas con candidatos a autoridades subnacionales | L14: Número de reuniones de presentación y coordinacion con candidatos a autoridades de los GSN | M14: Reunión | N14: Reporte | O14: Articulación temprana con candidatos a Gobernadores Regionales y Alcaldes Provinciales para asegurar continuidad técnica | W14: 1 | X14: 1 | Y14: 1 | Z14: 1 | AA14: 1 | AB14: =SUM(P14:AA14) -> 5
A15: D1 | B15: =IFERROR(CONCATENATE(A15,". ",VLOOKUP(A15,'results, prods y acts'!$A$2:$B$8,2,FALSE)),"") -> D1. Los procesos estratégicos y de soporte se realizan de forma eficaz y eficiente | C15: D1.5 | D15: =IFERROR(CONCATENATE(C15,". ",VLOOKUP(C15,'results, prods y acts'!$D$2:$E$12,2,FALSE)),CONCATENATE(C15,". ")) -> D1.5. Evaluación de los GSN | I15: D1.5.1 | J15: Diseño de la metodología de evaluación de las finanzas públicas en GSN | K15: =CONCATENATE(I15,". ",J15) -> D1.5.1. Diseño de la metodología de evaluación de las finanzas públicas en GSN | L15: Número de documento | M15: Documento | N15: Informe | O15: Se define una metodología ad hoc para la evaluación de la gestión de las finanzas públicas en GSN | T15: 1 | AB15: =SUM(P15:AA15) -> 1
A16: D1 | B16: =IFERROR(CONCATENATE(A16,". ",VLOOKUP(A16,'results, prods y acts'!$A$2:$B$8,2,FALSE)),"") -> D1. Los procesos estratégicos y de soporte se realizan de forma eficaz y eficiente | C16: D1.6 | D16: =IFERROR(CONCATENATE(C16,". ",VLOOKUP(C16,'results, prods y acts'!$D$2:$E$12,2,FALSE)),CONCATENATE(C16,". ")) -> D1.6. Gestión del Conocimiento y Sostenibilidad | I16: D1.6.1 | J16: Revisión y aprobación de publicaciones | K16: =CONCATENATE(I16,". ",J16) -> D1.6.1. Revisión y aprobación de publicaciones | L16: Número de informes | M16: Informe | N16: Documento de trabajo | O16: Se promueve la sostenibilidad del Programa | U16: 2 | AA16: 3 | AB16: =SUM(P16:AA16) -> 5
A17: R1 | B17: =IFERROR(CONCATENATE(A17,". ",VLOOKUP(A17,'results, prods y acts'!$A$2:$B$8,2,FALSE)),"") -> R1. Los procesos de gestión de gasto corriente vinculados a los servicios básicos priorizados a cargo de los GSN son más eficaces y eficientes | C17: P1 | D17: =IFERROR(CONCATENATE(C17,". ",VLOOKUP(C17,'results, prods y acts'!$D$2:$E$12,2,FALSE)),CONCATENATE(C17,". ")) -> P1. Asistencia técnica | E17: {=IFERROR(INDEX(_xlfn.TEXTSPLIT(I17,"."),2)&"."&INDEX(_xlfn.TEXTSPLIT(I17,"."),3),"")} -> P1.1 | F17: =IFERROR(CONCATENATE(E17,". ",VLOOKUP(E17,'results, prods y acts'!$G$2:$H$16,2,FALSE)),"") -> P1.1. Taller | G17: A nivel GSN | I17: R1.P1.1.1 | J17: Taller en la gestión de la programación, contrataciones y almacén | K17: =CONCATENATE(I17,". ",J17) -> R1.P1.1.1. Taller en la gestión de la programación, contrataciones y almacén | L17: Número de Talleres | M17: Taller | N17: Reporte de Taller | O17: Los GSNs mejoran sus procesos de gestión de abastecimiento | Q17: 1 | S17: 1 | AB17: =SUM(P17:AA17) -> 2
A18: R1 | B18: =IFERROR(CONCATENATE(A18,". ",VLOOKUP(A18,'results, prods y acts'!$A$2:$B$8,2,FALSE)),"") -> R1. Los procesos de gestión de gasto corriente vinculados a los servicios básicos priorizados a cargo de los GSN son más eficaces y eficientes | C18: P1 | D18: =IFERROR(CONCATENATE(C18,". ",VLOOKUP(C18,'results, prods y acts'!$D$2:$E$12,2,FALSE)),CONCATENATE(C18,". ")) -> P1. Asistencia técnica | E18: {=IFERROR(INDEX(_xlfn.TEXTSPLIT(I18,"."),2)&"."&INDEX(_xlfn.TEXTSPLIT(I18,"."),3),"")} -> P1.2 | F18: =IFERROR(CONCATENATE(E18,". ",VLOOKUP(E18,'results, prods y acts'!$G$2:$H$16,2,FALSE)),"") -> P1.2. Acompañamiento | G18: A nivel GSN | I18: R1.P1.2.1 | J18: Acompañamiento a los GSN en el proceso de programación de la demanda de bienes y servicios relacionados a servicios priorizados en educación y salud | K18: =CONCATENATE(I18,". ",J18) -> R1.P1.2.1. Acompañamiento a los GSN en el proceso de programación de la demanda de bienes y servicios relacionados a servicios priorizados en educación y salud | L18: Número de acompañamientos | M18: Acompañamiento | N18: Informe / Ficha de Seguimiento | O18: GSNs optimiza sus procesos de gestión. | P18: 5 | Q18: 4 | R18: 2 | S18: 4 | T18: 4 | V18: 1 | W18: 2 | X18: 3 | Y18: 4 | Z18: 1 | AB18: =SUM(P18:AA18) -> 30
A19: R1 | B19: =IFERROR(CONCATENATE(A19,". ",VLOOKUP(A19,'results, prods y acts'!$A$2:$B$8,2,FALSE)),"") -> R1. Los procesos de gestión de gasto corriente vinculados a los servicios básicos priorizados a cargo de los GSN son más eficaces y eficientes | C19: P1 | D19: =IFERROR(CONCATENATE(C19,". ",VLOOKUP(C19,'results, prods y acts'!$D$2:$E$12,2,FALSE)),CONCATENATE(C19,". ")) -> P1. Asistencia técnica | E19: {=IFERROR(INDEX(_xlfn.TEXTSPLIT(I19,"."),2)&"."&INDEX(_xlfn.TEXTSPLIT(I19,"."),3),"")} -> P1.2 | F19: =IFERROR(CONCATENATE(E19,". ",VLOOKUP(E19,'results, prods y acts'!$G$2:$H$16,2,FALSE)),"") -> P1.2. Acompañamiento | G19: A nivel GSN | I19: R1.P1.2.2 | J19: Acompañamiento a los GSN en las fases de los procesos de contratación de bienes y servicios relacionados al transporte y distribución de vacunas y Sulfato Ferroso | K19: =CONCATENATE(I19,". ",J19) -> R1.P1.2.2. Acompañamiento a los GSN en las fases de los procesos de contratación de bienes y servicios relacionados al transporte y distribución de vacunas y Sulfato Ferroso | L19: Número de acompañamientos | M19: GSN | N19: Ficha de Seguimiento | O19: GSN culminan procesos de contratación de los SBP | P19: 1 | Q19: 1 | R19: 3 | S19: 1 | T19: 1 | U19: 2 | V19: 2 | Y19: 3 | Z19: 2 | AB19: =SUM(P19:AA19) -> 16
A20: R1 | B20: =IFERROR(CONCATENATE(A20,". ",VLOOKUP(A20,'results, prods y acts'!$A$2:$B$8,2,FALSE)),"") -> R1. Los procesos de gestión de gasto corriente vinculados a los servicios básicos priorizados a cargo de los GSN son más eficaces y eficientes | C20: P1 | D20: =IFERROR(CONCATENATE(C20,". ",VLOOKUP(C20,'results, prods y acts'!$D$2:$E$12,2,FALSE)),CONCATENATE(C20,". ")) -> P1. Asistencia técnica | E20: {=IFERROR(INDEX(_xlfn.TEXTSPLIT(I20,"."),2)&"."&INDEX(_xlfn.TEXTSPLIT(I20,"."),3),"")} -> P1.2 | F20: =IFERROR(CONCATENATE(E20,". ",VLOOKUP(E20,'results, prods y acts'!$G$2:$H$16,2,FALSE)),"") -> P1.2. Acompañamiento | G20: A nivel GSN | I20: R1.P1.2.3 | J20: Acompañamiento en el seguimiento del proceso de distribución de vacunas, registro oportuno de entradas y salidas (Neas y PECOSAS) de las vacunas. | K20: =CONCATENATE(I20,". ",J20) -> R1.P1.2.3. Acompañamiento en el seguimiento del proceso de distribución de vacunas, registro oportuno de entradas y salidas (Neas y PECOSAS) de las vacunas. | L20: Número de acompañamientos | M20: Acompañamiento | N20: Ficha de Seguimiento | O20: GSN relacionado con los SBP realiza oportunamente la distribución de vacunas. | P20: 2 | Q20: 4 | R20: 2 | T20: 1 | U20: 4 | V20: 3 | X20: 2 | Z20: 3 | AA20: 2 | AB20: =SUM(P20:AA20) -> 23
A21: R1 | B21: =IFERROR(CONCATENATE(A21,". ",VLOOKUP(A21,'results, prods y acts'!$A$2:$B$8,2,FALSE)),"") -> R1. Los procesos de gestión de gasto corriente vinculados a los servicios básicos priorizados a cargo de los GSN son más eficaces y eficientes | C21: P1 | D21: =IFERROR(CONCATENATE(C21,". ",VLOOKUP(C21,'results, prods y acts'!$D$2:$E$12,2,FALSE)),CONCATENATE(C21,". ")) -> P1. Asistencia técnica | E21: {=IFERROR(INDEX(_xlfn.TEXTSPLIT(I21,"."),2)&"."&INDEX(_xlfn.TEXTSPLIT(I21,"."),3),"")} -> P1.2 | F21: =IFERROR(CONCATENATE(E21,". ",VLOOKUP(E21,'results, prods y acts'!$G$2:$H$16,2,FALSE)),"") -> P1.2. Acompañamiento | G21: A nivel GSN | I21: R1.P1.2.4 | J21: Acompañamiento en el seguimiento del proceso de distribución del sulfato ferroso y verificación del registro oportuno de entradas y salidas (Neas y PECOSAS) del sulfato ferroso | K21: =CONCATENATE(I21,". ",J21) -> R1.P1.2.4. Acompañamiento en el seguimiento del proceso de distribución del sulfato ferroso y verificación del registro oportuno de entradas y salidas (Neas y PECOSAS) del sulfato ferroso | L21: Número de acompañamientos | M21: Acompañamiento | N21: Ficha de Seguimiento | O21: GSN relacionados a los SBP realiza oportunamente la distribución del sulfato ferroso | P21: 1 | Q21: 2 | R21: 4 | T21: 1 | U21: 3 | V21: 3 | X21: 2 | Y21: 2 | Z21: 3 | AA21: 1 | AB21: =SUM(P21:AA21) -> 22
A22: R1 | B22: =IFERROR(CONCATENATE(A22,". ",VLOOKUP(A22,'results, prods y acts'!$A$2:$B$8,2,FALSE)),"") -> R1. Los procesos de gestión de gasto corriente vinculados a los servicios básicos priorizados a cargo de los GSN son más eficaces y eficientes | C22: P1 | D22: =IFERROR(CONCATENATE(C22,". ",VLOOKUP(C22,'results, prods y acts'!$D$2:$E$12,2,FALSE)),CONCATENATE(C22,". ")) -> P1. Asistencia técnica | E22: {=IFERROR(INDEX(_xlfn.TEXTSPLIT(I22,"."),2)&"."&INDEX(_xlfn.TEXTSPLIT(I22,"."),3),"")} -> P1.2 | F22: =IFERROR(CONCATENATE(E22,". ",VLOOKUP(E22,'results, prods y acts'!$G$2:$H$16,2,FALSE)),"") -> P1.2. Acompañamiento | G22: A nivel GSN | I22: R1.P1.2.5 | J22: Acompañamiento a los GSN en las fases de los procesos de contratación de bienes y servicios relacionados al transporte y distribución de material educativo. | K22: =CONCATENATE(I22,". ",J22) -> R1.P1.2.5. Acompañamiento a los GSN en las fases de los procesos de contratación de bienes y servicios relacionados al transporte y distribución de material educativo. | L22: Número de acompañamientos | M22: Acompañamiento | N22: Ficha de Seguimiento | O22: GSN culminan procesos de contratación de los SBP | P22: 1 | Q22: 11 | R22: 1 | V22: 1 | W22: 2 | Z22: 9 | AA22: 1 | AB22: =SUM(P22:AA22) -> 26
A23: R1 | B23: =IFERROR(CONCATENATE(A23,". ",VLOOKUP(A23,'results, prods y acts'!$A$2:$B$8,2,FALSE)),"") -> R1. Los procesos de gestión de gasto corriente vinculados a los servicios básicos priorizados a cargo de los GSN son más eficaces y eficientes | C23: P1 | D23: =IFERROR(CONCATENATE(C23,". ",VLOOKUP(C23,'results, prods y acts'!$D$2:$E$12,2,FALSE)),CONCATENATE(C23,". ")) -> P1. Asistencia técnica | E23: {=IFERROR(INDEX(_xlfn.TEXTSPLIT(I23,"."),2)&"."&INDEX(_xlfn.TEXTSPLIT(I23,"."),3),"")} -> P1.2 | F23: =IFERROR(CONCATENATE(E23,". ",VLOOKUP(E23,'results, prods y acts'!$G$2:$H$16,2,FALSE)),"") -> P1.2. Acompañamiento | G23: A nivel GSN | I23: R1.P1.2.6 | J23: Acompañamiento en el seguimiento del proceso de distribución del material educativo y verificación del registro oportuno de entradas y salidas (Neas y PECOSAS) del material educativo. | K23: =CONCATENATE(I23,". ",J23) -> R1.P1.2.6. Acompañamiento en el seguimiento del proceso de distribución del material educativo y verificación del registro oportuno de entradas y salidas (Neas y PECOSAS) del material educativo. | L23: Número de acompañamientos | M23: Acompañamiento | N23: Ficha de Seguimiento | O23: GSN relacionados a los SBP realiza oportunamente la distribución del material educativo | P23: 1 | Q23: 1 | R23: 5 | S23: 7 | T23: 3 | U23: 3 | V23: 1 | X23: 4 | Y23: 2 | AB23: =SUM(P23:AA23) -> 27
A24: R1 | B24: =IFERROR(CONCATENATE(A24,". ",VLOOKUP(A24,'results, prods y acts'!$A$2:$B$8,2,FALSE)),"") -> R1. Los procesos de gestión de gasto corriente vinculados a los servicios básicos priorizados a cargo de los GSN son más eficaces y eficientes | C24: P1 | D24: =IFERROR(CONCATENATE(C24,". ",VLOOKUP(C24,'results, prods y acts'!$D$2:$E$12,2,FALSE)),CONCATENATE(C24,". ")) -> P1. Asistencia técnica | E24: {=IFERROR(INDEX(_xlfn.TEXTSPLIT(I24,"."),2)&"."&INDEX(_xlfn.TEXTSPLIT(I24,"."),3),"")} -> P1.2 | F24: =IFERROR(CONCATENATE(E24,". ",VLOOKUP(E24,'results, prods y acts'!$G$2:$H$16,2,FALSE)),"") -> P1.2. Acompañamiento | G24: A nivel GSN | I24: R1.P1.2.7 | J24: Acompañamiento a los GSNs en el proceso del seguimiento de la ejecución presupuestaria de ingresos y gastos. | K24: =CONCATENATE(I24,". ",J24) -> R1.P1.2.7. Acompañamiento a los GSNs en el proceso del seguimiento de la ejecución presupuestaria de ingresos y gastos. | L24: Número de acompañamientos | M24: Acompañamiento | N24: Ficha de Seguimiento | O24: Los GSNs se encuentran alertados sobre los avances en la ejecución presupuestaria. | R24: 4 | S24: 1 | T24: 3 | U24: 1 | V24: 2 | W24: 4 | Y24: 5 | Z24: 3 | AA24: 1 | AB24: =SUM(P24:AA24) -> 24
A25: R1 | B25: =IFERROR(CONCATENATE(A25,". ",VLOOKUP(A25,'results, prods y acts'!$A$2:$B$8,2,FALSE)),"") -> R1. Los procesos de gestión de gasto corriente vinculados a los servicios básicos priorizados a cargo de los GSN son más eficaces y eficientes | C25: P1 | D25: =IFERROR(CONCATENATE(C25,". ",VLOOKUP(C25,'results, prods y acts'!$D$2:$E$12,2,FALSE)),CONCATENATE(C25,". ")) -> P1. Asistencia técnica | E25: {=IFERROR(INDEX(_xlfn.TEXTSPLIT(I25,"."),2)&"."&INDEX(_xlfn.TEXTSPLIT(I25,"."),3),"")} -> P1.2 | F25: =IFERROR(CONCATENATE(E25,". ",VLOOKUP(E25,'results, prods y acts'!$G$2:$H$16,2,FALSE)),"") -> P1.2. Acompañamiento | G25: A nivel GSN | I25: R1.P1.2.8 | J25: Acompañamiento a los responsables designados en la elaboración del Plan de trabajo para la implementación de mejora de los almacenes relacionados a los SBP. | K25: =CONCATENATE(I25,". ",J25) -> R1.P1.2.8. Acompañamiento a los responsables designados en la elaboración del Plan de trabajo para la implementación de mejora de los almacenes relacionados a los SBP. | L25: Número de acompañamientos | M25: Acompañamiento | N25: Ficha de Seguimiento | O25: UEs de sector de Educación y/o Salud cuentan con plan de trabajo elaborado para la mejora de los almacenes a los SBP | Q25: 4 | R25: 3 | S25: 4 | T25: 2 | V25: 1 | W25: 4 | X25: 1 | Y25: 1 | AB25: =SUM(P25:AA25) -> 20
A26: R1 | B26: =IFERROR(CONCATENATE(A26,". ",VLOOKUP(A26,'results, prods y acts'!$A$2:$B$8,2,FALSE)),"") -> R1. Los procesos de gestión de gasto corriente vinculados a los servicios básicos priorizados a cargo de los GSN son más eficaces y eficientes | C26: P1 | D26: =IFERROR(CONCATENATE(C26,". ",VLOOKUP(C26,'results, prods y acts'!$D$2:$E$12,2,FALSE)),CONCATENATE(C26,". ")) -> P1. Asistencia técnica | E26: {=IFERROR(INDEX(_xlfn.TEXTSPLIT(I26,"."),2)&"."&INDEX(_xlfn.TEXTSPLIT(I26,"."),3),"")} -> P1.2 | F26: =IFERROR(CONCATENATE(E26,". ",VLOOKUP(E26,'results, prods y acts'!$G$2:$H$16,2,FALSE)),"") -> P1.2. Acompañamiento | G26: A nivel GSN | I26: R1.P1.2.9 | J26: Acompañamiento a los responsables designados en el proceso de implementación del Plan de trabajo de mejora de los almacenes relacionados a los SBP. | K26: =CONCATENATE(I26,". ",J26) -> R1.P1.2.9. Acompañamiento a los responsables designados en el proceso de implementación del Plan de trabajo de mejora de los almacenes relacionados a los SBP. | L26: Número de acompañamientos | M26: Acompañamiento | N26: Ficha de Seguimiento | O26: UEs de sector de Educación y/o Salud implementan mejoras en los almacenes. | P26: 3 | Q26: 11 | R26: 2 | S26: 2 | T26: 1 | U26: 2 | V26: 3 | W26: 1 | X26: 2 | Z26: 2 | AB26: =SUM(P26:AA26) -> 29
A27: R1 | B27: =IFERROR(CONCATENATE(A27,". ",VLOOKUP(A27,'results, prods y acts'!$A$2:$B$8,2,FALSE)),"") -> R1. Los procesos de gestión de gasto corriente vinculados a los servicios básicos priorizados a cargo de los GSN son más eficaces y eficientes | C27: P1 | D27: =IFERROR(CONCATENATE(C27,". ",VLOOKUP(C27,'results, prods y acts'!$D$2:$E$12,2,FALSE)),CONCATENATE(C27,". ")) -> P1. Asistencia técnica | E27: {=IFERROR(INDEX(_xlfn.TEXTSPLIT(I27,"."),2)&"."&INDEX(_xlfn.TEXTSPLIT(I27,"."),3),"")} -> P1.2 | F27: =IFERROR(CONCATENATE(E27,". ",VLOOKUP(E27,'results, prods y acts'!$G$2:$H$16,2,FALSE)),"") -> P1.2. Acompañamiento | G27: A nivel GSN | I27: R1.P1.2.11 | J27: Acompañamiento a los GSN en el proceso de planificación de las ACR | K27: =CONCATENATE(I27,". ",J27) -> R1.P1.2.11. Acompañamiento a los GSN en el proceso de planificación de las ACR | L27: Número de acompañamientos | M27: Acompañamiento | N27: Ficha de Seguimiento | O27: Plan Operativo (POI) de SERNANP aprobado | S27: 3 | AB27: =SUM(P27:AA27) -> 3
A28: R1 | B28: =IFERROR(CONCATENATE(A28,". ",VLOOKUP(A28,'results, prods y acts'!$A$2:$B$8,2,FALSE)),"") -> R1. Los procesos de gestión de gasto corriente vinculados a los servicios básicos priorizados a cargo de los GSN son más eficaces y eficientes | C28: P1 | D28: =IFERROR(CONCATENATE(C28,". ",VLOOKUP(C28,'results, prods y acts'!$D$2:$E$12,2,FALSE)),CONCATENATE(C28,". ")) -> P1. Asistencia técnica | E28: {=IFERROR(INDEX(_xlfn.TEXTSPLIT(I28,"."),2)&"."&INDEX(_xlfn.TEXTSPLIT(I28,"."),3),"")} -> P1.2 | F28: =IFERROR(CONCATENATE(E28,". ",VLOOKUP(E28,'results, prods y acts'!$G$2:$H$16,2,FALSE)),"") -> P1.2. Acompañamiento | G28: A nivel GSN | I28: R1.P1.2.12 | J28: Acompañamiento a los GSN en el proceso de programación de la demanda de bienes y servicios relacionados a los ACR | K28: =CONCATENATE(I28,". ",J28) -> R1.P1.2.12. Acompañamiento a los GSN en el proceso de programación de la demanda de bienes y servicios relacionados a los ACR | L28: Número de acompañamientos | M28: Acompañamiento | N28: Informe / Ficha de Seguimiento | O28: GSNs optimiza sus procesos de gestión. | T28: 3 | X28: 3 | AB28: =SUM(P28:AA28) -> 6
A29: R1 | B29: =IFERROR(CONCATENATE(A29,". ",VLOOKUP(A29,'results, prods y acts'!$A$2:$B$8,2,FALSE)),"") -> R1. Los procesos de gestión de gasto corriente vinculados a los servicios básicos priorizados a cargo de los GSN son más eficaces y eficientes | C29: P1 | D29: =IFERROR(CONCATENATE(C29,". ",VLOOKUP(C29,'results, prods y acts'!$D$2:$E$12,2,FALSE)),CONCATENATE(C29,". ")) -> P1. Asistencia técnica | E29: {=IFERROR(INDEX(_xlfn.TEXTSPLIT(I29,"."),2)&"."&INDEX(_xlfn.TEXTSPLIT(I29,"."),3),"")} -> P1.2 | F29: =IFERROR(CONCATENATE(E29,". ",VLOOKUP(E29,'results, prods y acts'!$G$2:$H$16,2,FALSE)),"") -> P1.2. Acompañamiento | G29: A nivel GSN | I29: R1.P1.2.13 | J29: Acompañamiento a los GSN en las fases de los procesos de contratación de bienes y servicios relacionados con las actividades de las ACR | K29: =CONCATENATE(I29,". ",J29) -> R1.P1.2.13. Acompañamiento a los GSN en las fases de los procesos de contratación de bienes y servicios relacionados con las actividades de las ACR | L29: Número de acompañamientos | M29: GSN | N29: Ficha de Seguimiento | O29: GSN culminan procesos de contratación de los SBP | T29: 3 | V29: 3 | Y29: 3 | AB29: =SUM(P29:AA29) -> 9
A30: R1 | B30: =IFERROR(CONCATENATE(A30,". ",VLOOKUP(A30,'results, prods y acts'!$A$2:$B$8,2,FALSE)),"") -> R1. Los procesos de gestión de gasto corriente vinculados a los servicios básicos priorizados a cargo de los GSN son más eficaces y eficientes | C30: P1 | D30: =IFERROR(CONCATENATE(C30,". ",VLOOKUP(C30,'results, prods y acts'!$D$2:$E$12,2,FALSE)),CONCATENATE(C30,". ")) -> P1. Asistencia técnica | E30: {=IFERROR(INDEX(_xlfn.TEXTSPLIT(I30,"."),2)&"."&INDEX(_xlfn.TEXTSPLIT(I30,"."),3),"")} -> P1.2 | F30: =IFERROR(CONCATENATE(E30,". ",VLOOKUP(E30,'results, prods y acts'!$G$2:$H$16,2,FALSE)),"") -> P1.2. Acompañamiento | G30: A nivel GSN | I30: R1.P1.2.14 | J30: Acompañamiento a los GSNs en el proceso del seguimiento de la ejecución presupuestaria de gastos de las ACR | K30: =CONCATENATE(I30,". ",J30) -> R1.P1.2.14. Acompañamiento a los GSNs en el proceso del seguimiento de la ejecución presupuestaria de gastos de las ACR | L30: Número de acompañamientos | M30: Acompañamiento | N30: Ficha de Seguimiento | O30: Los GSNs se encuentran alertados sobre los avances en la ejecución presupuestaria. | U30: 3 | X30: 3 | AB30: =SUM(P30:AA30) -> 6
A31: R1 | B31: =IFERROR(CONCATENATE(A31,". ",VLOOKUP(A31,'results, prods y acts'!$A$2:$B$8,2,FALSE)),"") -> R1. Los procesos de gestión de gasto corriente vinculados a los servicios básicos priorizados a cargo de los GSN son más eficaces y eficientes | C31: P1 | D31: =IFERROR(CONCATENATE(C31,". ",VLOOKUP(C31,'results, prods y acts'!$D$2:$E$12,2,FALSE)),CONCATENATE(C31,". ")) -> P1. Asistencia técnica | E31: {=IFERROR(INDEX(_xlfn.TEXTSPLIT(I31,"."),2)&"."&INDEX(_xlfn.TEXTSPLIT(I31,"."),3),"")} -> P1.2 | F31: =IFERROR(CONCATENATE(E31,". ",VLOOKUP(E31,'results, prods y acts'!$G$2:$H$16,2,FALSE)),"") -> P1.2. Acompañamiento | G31: A nivel GSN | I31: R1.P1.2.15 | J31: Acompañamiento a los GSN en la elaboración de la metodología de evaluación de las finanzas públicas (PEFA) | K31: =CONCATENATE(I31,". ",J31) -> R1.P1.2.15. Acompañamiento a los GSN en la elaboración de la metodología de evaluación de las finanzas públicas (PEFA) | L31: Número de acompañamientos | M31: Acompañamiento | N31: Ficha de Seguimiento | O31: GSN cuentan con metodología de evaluación de las finanzas públicas (PEFA) | Z31: 10 | AB31: =SUM(P31:AA31) -> 10
A32: R1 | B32: =IFERROR(CONCATENATE(A32,". ",VLOOKUP(A32,'results, prods y acts'!$A$2:$B$8,2,FALSE)),"") -> R1. Los procesos de gestión de gasto corriente vinculados a los servicios básicos priorizados a cargo de los GSN son más eficaces y eficientes | C32: P1 | D32: =IFERROR(CONCATENATE(C32,". ",VLOOKUP(C32,'results, prods y acts'!$D$2:$E$12,2,FALSE)),CONCATENATE(C32,". ")) -> P1. Asistencia técnica | E32: {=IFERROR(INDEX(_xlfn.TEXTSPLIT(I32,"."),2)&"."&INDEX(_xlfn.TEXTSPLIT(I32,"."),3),"")} -> P1.3 | F32: =IFERROR(CONCATENATE(E32,". ",VLOOKUP(E32,'results, prods y acts'!$G$2:$H$16,2,FALSE)),"") -> P1.3. Reuniones de retroalimentación | G32: A nivel GSN | I32: R1.P1.3.1 | J32: Reuniones de retroalimentación del avance y resultado de la distribución de vacunas y material educativo con los GSN. | K32: =CONCATENATE(I32,". ",J32) -> R1.P1.3.1. Reuniones de retroalimentación del avance y resultado de la distribución de vacunas y material educativo con los GSN. | L32: Número de reuniones | M32: Reunión | N32: Ficha de Seguimiento | O32: UEs - Sector Educación y Salud, informado y alertado de los avances y resultados de la distribución de vacunas y material educativo. | Q32: 3 | R32: 3 | S32: 3 | U32: 3 | V32: 1 | W32: 1 | X32: 2 | Y32: 1 | Z32: 2 | AA32: 1 | AB32: =SUM(P32:AA32) -> 20
A33: R1 | B33: =IFERROR(CONCATENATE(A33,". ",VLOOKUP(A33,'results, prods y acts'!$A$2:$B$8,2,FALSE)),"") -> R1. Los procesos de gestión de gasto corriente vinculados a los servicios básicos priorizados a cargo de los GSN son más eficaces y eficientes | C33: P2 | D33: =IFERROR(CONCATENATE(C33,". ",VLOOKUP(C33,'results, prods y acts'!$D$2:$E$12,2,FALSE)),CONCATENATE(C33,". ")) -> P2. Fortalecimiento de capacidades | E33: {=IFERROR(INDEX(_xlfn.TEXTSPLIT(I33,"."),2)&"."&INDEX(_xlfn.TEXTSPLIT(I33,"."),3),"")} -> P2.1 | F33: =IFERROR(CONCATENATE(E33,". ",VLOOKUP(E33,'results, prods y acts'!$G$2:$H$16,2,FALSE)),"") -> P2.1. Cursos | G33: A nivel GSN | I33: R1.P2.1.1 | J33: Curso (Programa Especial) en temas relacionados con la cadena de abastecimiento. | K33: =CONCATENATE(I33,". ",J33) -> R1.P2.1.1. Curso (Programa Especial) en temas relacionados con la cadena de abastecimiento. | L33: Número de cursos | M33: Curso | N33: Informe | O33: Fortalecer conocimiento sobre metas de la cadena de abastecimiento. | V33: 1 | AB33: =SUM(P33:AA33) -> 1
A34: R1 | B34: =IFERROR(CONCATENATE(A34,". ",VLOOKUP(A34,'results, prods y acts'!$A$2:$B$8,2,FALSE)),"") -> R1. Los procesos de gestión de gasto corriente vinculados a los servicios básicos priorizados a cargo de los GSN son más eficaces y eficientes | C34: P2 | D34: =IFERROR(CONCATENATE(C34,". ",VLOOKUP(C34,'results, prods y acts'!$D$2:$E$12,2,FALSE)),CONCATENATE(C34,". ")) -> P2. Fortalecimiento de capacidades | E34: {=IFERROR(INDEX(_xlfn.TEXTSPLIT(I34,"."),2)&"."&INDEX(_xlfn.TEXTSPLIT(I34,"."),3),"")} -> P2.1 | F34: =IFERROR(CONCATENATE(E34,". ",VLOOKUP(E34,'results, prods y acts'!$G$2:$H$16,2,FALSE)),"") -> P2.1. Cursos | G34: A nivel GSN | I34: R1.P2.1.2 | J34: Curso en Instrumentos de Sostenibilidad Financiera | K34: =CONCATENATE(I34,". ",J34) -> R1.P2.1.2. Curso en Instrumentos de Sostenibilidad Financiera | L34: Número de cursos | M34: Curso | N34: Informe | O34: Gerencias de recursos naturales capacitados en el uso de instrumentos de sostenibilidad financiera | Q34: 1 | AB34: =SUM(P34:AA34) -> 1
A35: R1 | B35: =IFERROR(CONCATENATE(A35,". ",VLOOKUP(A35,'results, prods y acts'!$A$2:$B$8,2,FALSE)),"") -> R1. Los procesos de gestión de gasto corriente vinculados a los servicios básicos priorizados a cargo de los GSN son más eficaces y eficientes | C35: P2 | D35: =IFERROR(CONCATENATE(C35,". ",VLOOKUP(C35,'results, prods y acts'!$D$2:$E$12,2,FALSE)),CONCATENATE(C35,". ")) -> P2. Fortalecimiento de capacidades | E35: {=IFERROR(INDEX(_xlfn.TEXTSPLIT(I35,"."),2)&"."&INDEX(_xlfn.TEXTSPLIT(I35,"."),3),"")} -> P2.3 | F35: =IFERROR(CONCATENATE(E35,". ",VLOOKUP(E35,'results, prods y acts'!$G$2:$H$16,2,FALSE)),"") -> P2.3. Capacitación ad hoc | G35: A nivel GSN | I35: R1.P2.3.1 | J35: Capacitación ad hoc para la programación de bienes y servicios de los SBP | K35: =CONCATENATE(I35,". ",J35) -> R1.P2.3.1. Capacitación ad hoc para la programación de bienes y servicios de los SBP | L35: Número de capacitaciones | M35: Capacitación | N35: Informe y Actas | O35: Personal técnico involucrado en la programación de CMN se encuentran capacitados en el GSN. | P35: 1 | Q35: 3 | R35: 3 | V35: 2 | W35: 1 | AB35: =SUM(P35:AA35) -> 10
A36: R1 | B36: =IFERROR(CONCATENATE(A36,". ",VLOOKUP(A36,'results, prods y acts'!$A$2:$B$8,2,FALSE)),"") -> R1. Los procesos de gestión de gasto corriente vinculados a los servicios básicos priorizados a cargo de los GSN son más eficaces y eficientes | C36: P2 | D36: =IFERROR(CONCATENATE(C36,". ",VLOOKUP(C36,'results, prods y acts'!$D$2:$E$12,2,FALSE)),CONCATENATE(C36,". ")) -> P2. Fortalecimiento de capacidades | E36: {=IFERROR(INDEX(_xlfn.TEXTSPLIT(I36,"."),2)&"."&INDEX(_xlfn.TEXTSPLIT(I36,"."),3),"")} -> P2.3 | F36: =IFERROR(CONCATENATE(E36,". ",VLOOKUP(E36,'results, prods y acts'!$G$2:$H$16,2,FALSE)),"") -> P2.3. Capacitación ad hoc | G36: A nivel GSN | I36: R1.P2.3.2 | J36: Capacitación ad hoc o Curso de capacidades en la fases de contratación de bienes y servicios vinculados con los SBP | K36: =CONCATENATE(I36,". ",J36) -> R1.P2.3.2. Capacitación ad hoc o Curso de capacidades en la fases de contratación de bienes y servicios vinculados con los SBP | L36: Número de capacitaciones | M36: Curso y/o capacitación | N36: Informe y Actas | O36: Personal del OEC del GSN, se encuentran capacitados. | R36: 2 | T36: 4 | U36: 1 | V36: 3 | AB36: =SUM(P36:AA36) -> 10
A37: R1 | B37: =IFERROR(CONCATENATE(A37,". ",VLOOKUP(A37,'results, prods y acts'!$A$2:$B$8,2,FALSE)),"") -> R1. Los procesos de gestión de gasto corriente vinculados a los servicios básicos priorizados a cargo de los GSN son más eficaces y eficientes | C37: P2 | D37: =IFERROR(CONCATENATE(C37,". ",VLOOKUP(C37,'results, prods y acts'!$D$2:$E$12,2,FALSE)),CONCATENATE(C37,". ")) -> P2. Fortalecimiento de capacidades | E37: {=IFERROR(INDEX(_xlfn.TEXTSPLIT(I37,"."),2)&"."&INDEX(_xlfn.TEXTSPLIT(I37,"."),3),"")} -> P2.3 | F37: =IFERROR(CONCATENATE(E37,". ",VLOOKUP(E37,'results, prods y acts'!$G$2:$H$16,2,FALSE)),"") -> P2.3. Capacitación ad hoc | G37: A nivel GSN | I37: R1.P2.3.3 | J37: Capacitación ad hoc en Gestión de Almacenes de los SBP | K37: =CONCATENATE(I37,". ",J37) -> R1.P2.3.3. Capacitación ad hoc en Gestión de Almacenes de los SBP | L37: Número de capacitaciones | M37: Capacitación | N37: Informe y Actas | O37: Personal técnico involucrado en la gestión de almacenes encuentren capacitados en el GSN | R37: 1 | S37: 1 | W37: 1 | Y37: 2 | AB37: =SUM(P37:AA37) -> 5
A38: R1 | B38: =IFERROR(CONCATENATE(A38,". ",VLOOKUP(A38,'results, prods y acts'!$A$2:$B$8,2,FALSE)),"") -> R1. Los procesos de gestión de gasto corriente vinculados a los servicios básicos priorizados a cargo de los GSN son más eficaces y eficientes | C38: P2 | D38: =IFERROR(CONCATENATE(C38,". ",VLOOKUP(C38,'results, prods y acts'!$D$2:$E$12,2,FALSE)),CONCATENATE(C38,". ")) -> P2. Fortalecimiento de capacidades | E38: {=IFERROR(INDEX(_xlfn.TEXTSPLIT(I38,"."),2)&"."&INDEX(_xlfn.TEXTSPLIT(I38,"."),3),"")} -> P2.5 | F38: =IFERROR(CONCATENATE(E38,". ",VLOOKUP(E38,'results, prods y acts'!$G$2:$H$16,2,FALSE)),"") -> P2.5. Charla | G38: A nivel GSN | I38: R1.P2.5.1 | J38: Charla para la elaboración del PAC 2023, PMBSyO 2024-2026, adecuada elaboración de las solicitudes de pedido, elaboración de especificaciones técnicas y términos de referencia para bienes y servicios y almacenes de los SBP | K38: =CONCATENATE(I38,". ",J38) -> R1.P2.5.1. Charla para la elaboración del PAC 2023, PMBSyO 2024-2026, adecuada elaboración de las solicitudes de pedido, elaboración de especificaciones técnicas y términos de referencia para bienes y servicios y almacenes de los SBP | L38: Número de charlas | M38: Charla | N38: Ficha de Seguimiento | O38: Personal de los GSN responsable de realizar pedidos se encuentra capacitado (Charla virtual). | P38: 2 | Q38: 6 | R38: 3 | S38: 2 | T38: 1 | V38: 6 | W38: 4 | X38: 1 | Y38: 1 | Z38: 1 | AB38: =SUM(P38:AA38) -> 27
A39: R1 | B39: =IFERROR(CONCATENATE(A39,". ",VLOOKUP(A39,'results, prods y acts'!$A$2:$B$8,2,FALSE)),"") -> R1. Los procesos de gestión de gasto corriente vinculados a los servicios básicos priorizados a cargo de los GSN son más eficaces y eficientes | C39: P2 | D39: =IFERROR(CONCATENATE(C39,". ",VLOOKUP(C39,'results, prods y acts'!$D$2:$E$12,2,FALSE)),CONCATENATE(C39,". ")) -> P2. Fortalecimiento de capacidades | E39: {=IFERROR(INDEX(_xlfn.TEXTSPLIT(I39,"."),2)&"."&INDEX(_xlfn.TEXTSPLIT(I39,"."),3),"")} -> P2.5 | F39: =IFERROR(CONCATENATE(E39,". ",VLOOKUP(E39,'results, prods y acts'!$G$2:$H$16,2,FALSE)),"") -> P2.5. Charla | G39: A nivel GSN | I39: R1.P2.5.2 | J39: Charla para la elaboración del POI, PMBSyO 2027-2029, adecuada elaboración de las solicitudes de pedido, elaboración de especificaciones técnicas y términos de referencia para bienes y servicios para ACR | K39: =CONCATENATE(I39,". ",J39) -> R1.P2.5.2. Charla para la elaboración del POI, PMBSyO 2027-2029, adecuada elaboración de las solicitudes de pedido, elaboración de especificaciones técnicas y términos de referencia para bienes y servicios para ACR | L39: Número de charlas | M39: Charla | N39: Ficha de Seguimiento | O39: Personal de las ACR responsable de realizar pedidos se encuentra capacitado (Charla virtual). | Q39: 3 | V39: 3 | AB39: =SUM(P39:AA39) -> 6
A40: R1 | B40: =IFERROR(CONCATENATE(A40,". ",VLOOKUP(A40,'results, prods y acts'!$A$2:$B$8,2,FALSE)),"") -> R1. Los procesos de gestión de gasto corriente vinculados a los servicios básicos priorizados a cargo de los GSN son más eficaces y eficientes | C40: P2 | D40: =IFERROR(CONCATENATE(C40,". ",VLOOKUP(C40,'results, prods y acts'!$D$2:$E$12,2,FALSE)),CONCATENATE(C40,". ")) -> P2. Fortalecimiento de capacidades | E40: {=IFERROR(INDEX(_xlfn.TEXTSPLIT(I40,"."),2)&"."&INDEX(_xlfn.TEXTSPLIT(I40,"."),3),"")} -> P2.5 | F40: =IFERROR(CONCATENATE(E40,". ",VLOOKUP(E40,'results, prods y acts'!$G$2:$H$16,2,FALSE)),"") -> P2.5. Charla | G40: A nivel GSN | I40: R1.P2.5.3 | J40: Charla especializada en Presupuesto Público | K40: =CONCATENATE(I40,". ",J40) -> R1.P2.5.3. Charla especializada en Presupuesto Público | L40: Número de charlas | M40: Charla | N40: Ficha de Seguimiento | O40: Personal del Ministerio Público capacitado | R40: 1 | V40: 1 | AB40: =SUM(P40:AA40) -> 2
...

Sheet POA2026_ej (2)
A1: Resultado_cod | B1: Resultado | C1: Producto_cod | D1: Producto | E1: Tipo_producto_cod | F1: Tipo de producto | G1: Nivel | H1: Entidad_p6 | I1: Actividad_cod | J1: Actividad_name | K1: Actividad | L1: Indicador | M1: Unidad de medida | N1: Medio de verificación | O1: Logro Esperado | P1: ene_pl | Q1: feb_pl | R1: mar_pl | S1: abr_pl | T1: may_pl | U1: jun_pl | V1: jul_pl | W1: ago_pl | X1: set_pl | Y1: oct_pl | Z1: nov_pl | AA1: dic_pl | AB1: Pl_total | AC1: ene_ej | AD1: feb_ej | AE1: mar_ej | AF1: abr_ej | AG1: may_ej | AH1: jun_ej | AI1: jul_ej | AJ1: ago_ej | AK1: set_ej | AL1: oct_ej | AM1: nov_ej | AN1: dic_ej | AO1: Ej_total
A2: D1 | B2: =IFERROR(CONCATENATE(A2,". ",VLOOKUP(A2,'results, prods y acts'!$A$2:$B$8,2,FALSE)),"") -> D1. Los procesos estratégicos y de soporte se realizan de forma eficaz y eficiente | C2: D1.1 | D2: =IFERROR(CONCATENATE(C2,". ",VLOOKUP(C2,'results, prods y acts'!$D$2:$E$12,2,FALSE)),CONCATENATE(C2,". ")) -> D1.1. Informes semestrales | I2: D1.1.1 | J2: Envío a SECO | K2: =CONCATENATE(I2,". ",J2) -> D1.1.1. Envío a SECO | L2: Número de informes | M2: Informe | N2: Correo de envío | O2: Informes enviados en el tiempo esperado | Q2: 1 | W2: 1 | AB2: =SUM(P2:AA2) -> 2
A3: D1 | B3: =IFERROR(CONCATENATE(A3,". ",VLOOKUP(A3,'results, prods y acts'!$A$2:$B$8,2,FALSE)),"") -> D1. Los procesos estratégicos y de soporte se realizan de forma eficaz y eficiente | C3: D1.1 | D3: =IFERROR(CONCATENATE(C3,". ",VLOOKUP(C3,'results, prods y acts'!$D$2:$E$12,2,FALSE)),CONCATENATE(C3,". ")) -> D1.1. Informes semestrales | I3: D1.1.2 | J3: Absolución de comentarios | K3: =CONCATENATE(I3,". ",J3) -> D1.1.2. Absolución de comentarios | L3: Número de respuestas | M3: Informe | N3: Correo de envío | O3: Informes enviados en el tiempo esperado | Q3: 1 | W3: 1 | AB3: =SUM(P3:AA3) -> 2
A4: R1 | B4: =IFERROR(CONCATENATE(A4,". ",VLOOKUP(A4,'results, prods y acts'!$A$2:$B$8,2,FALSE)),"") -> R1. Los procesos de gestión de gasto corriente vinculados a los servicios básicos priorizados a cargo de los GSN son más eficaces y eficientes | C4: P2 | D4: =IFERROR(CONCATENATE(C4,". ",VLOOKUP(C4,'results, prods y acts'!$D$2:$E$12,2,FALSE)),CONCATENATE(C4,". ")) -> P2. Fortalecimiento de capacidades | E4: {=IFERROR(INDEX(_xlfn.TEXTSPLIT(I4,"."),2)&"."&INDEX(_xlfn.TEXTSPLIT(I4,"."),3),"")} -> P2.1 | F4: =IFERROR(CONCATENATE(E4,". ",VLOOKUP(E4,'results, prods y acts'!$G$2:$H$16,2,FALSE)),"") -> P2.1. Cursos | G4: A nivel GSN | I4: R1.P2.1.2 | J4: Curso en Instrumentos de Sostenibilidad Financiera | K4: =CONCATENATE(I4,". ",J4) -> R1.P2.1.2. Curso en Instrumentos de Sostenibilidad Financiera | L4: Número de cursos | M4: Curso | N4: Informe | O4: Gerencias de recursos naturales capacitados en el uso de instrumentos de sostenibilidad financiera | Q4: 1 | AB4: =SUM(P4:AA4) -> 1
A5: CB | B5: =IFERROR(CONCATENATE(A5,". ",VLOOKUP(A5,'results, prods y acts'!$A$2:$B$8,2,FALSE)),"") -> CB. Conservación de la Biodiversidad y Lucha contra el Cambio Climático | C5: P3 | D5: =IFERROR(CONCATENATE(C5,". ",VLOOKUP(C5,'results, prods y acts'!$D$2:$E$12,2,FALSE)),CONCATENATE(C5,". ")) -> P3. Instrumentos de mejora de la gestión | E5: {=IFERROR(INDEX(_xlfn.TEXTSPLIT(I5,"."),2)&"."&INDEX(_xlfn.TEXTSPLIT(I5,"."),3),"")} -> P3.5 | F5: =IFERROR(CONCATENATE(E5,". ",VLOOKUP(E5,'results, prods y acts'!$G$2:$H$16,2,FALSE)),"") -> P3.5. Propuesta de modificación técnico-administrativa a nivel sectorial | G5: A nivel GSN | I5: CB.P3.5.1 | J5: Guía para la entrega de los servicios de vigilancia y control, en las fases de monitoreo y retroalimentación | K5: =CONCATENATE(I5,". ",J5) -> CB.P3.5.1. Guía para la entrega de los servicios de vigilancia y control, en las fases de monitoreo y retroalimentación | L5: Numero de propuestas | M5: Documento | N5: Guia o Protocolo | O5: SERNANP fortalece su institucionalidad en vigilancia y control | R5: 1 | AB5: =SUM(P5:AA5) -> 1
A6: CB | B6: =IFERROR(CONCATENATE(A6,". ",VLOOKUP(A6,'results, prods y acts'!$A$2:$B$8,2,FALSE)),"") -> CB. Conservación de la Biodiversidad y Lucha contra el Cambio Climático | C6: P5 | D6: =IFERROR(CONCATENATE(C6,". ",VLOOKUP(C6,'results, prods y acts'!$D$2:$E$12,2,FALSE)),CONCATENATE(C6,". ")) -> P5. Instrumentos de Gestión del Conocimiento (Publicaciones) | E6: {=IFERROR(INDEX(_xlfn.TEXTSPLIT(I6,"."),2)&"."&INDEX(_xlfn.TEXTSPLIT(I6,"."),3),"")} -> P5.2 | F6: =IFERROR(CONCATENATE(E6,". ",VLOOKUP(E6,'results, prods y acts'!$G$2:$H$16,2,FALSE)),"") -> P5.2. Documentos de buenas prácticas y lecciones aprendidas | G6: A nivel GSN | I6: CB.P5.2.1 | J6: Documento de Buenas practicas en el uso del Mapa de Actores | K6: =CONCATENATE(I6,". ",J6) -> CB.P5.2.1. Documento de Buenas practicas en el uso del Mapa de Actores | L6: Numero de publicaciones | M6: Documento | N6: Publicación | O6: Difusión de buenas practicas en el uso de Mapa de Actores | Y6: 1 | AB6: =SUM(P6:AA6) -> 1
A7: CB | B7: =IFERROR(CONCATENATE(A7,". ",VLOOKUP(A7,'results, prods y acts'!$A$2:$B$8,2,FALSE)),"") -> CB. Conservación de la Biodiversidad y Lucha contra el Cambio Climático | C7: P6 | D7: =IFERROR(CONCATENATE(C7,". ",VLOOKUP(C7,'results, prods y acts'!$D$2:$E$12,2,FALSE)),CONCATENATE(C7,". ")) -> P6. | F7: =IFERROR(CONCATENATE(E7,". ",VLOOKUP(E7,'results, prods y acts'!$G$2:$H$16,2,FALSE)),"") | G7: A nivel nacional | H7: Entes rectores | I7: CB.6.1 | J7: Planes de trabajo con entes rectores (SERNANP, OSINFOR, MINAM) | K7: =CONCATENATE(I7,". ",J7) -> CB.6.1. Planes de trabajo con entes rectores (SERNANP, OSINFOR, MINAM) | L7: Numeros de planes | M7: Planes | N7: Planes | O7: Establecer intervenciones articuladas con los órganos rectores en materia ambiental | Q7: 2 | U7: 1 | AB7: =SUM(P7:AA7) -> 3

Sheet results, prods y acts
A1: Codigo | B1: Resultado | D1: Codigo | E1: Producto | G1: Codigo | H1: Tipo de producto
A2: D1 | B2: Los procesos estratégicos y de soporte se realizan de forma eficaz y eficiente | D2: D1.1 | E2: Informes semestrales | G2: P1.1 | H2: Taller
A3: R1 | B3: Los procesos de gestión de gasto corriente vinculados a los servicios básicos priorizados a cargo de los GSN son más eficaces y eficientes | D3: D1.2 | E3: Planificación Operativa | G3: P1.2 | H3: Acompañamiento
A4: R2 | B4: Los procesos de gestión de gasto de capital vinculados a los servicios priorizados a cargo de los GSN son más eficaces y eficientes | D4: D1.3 | E4: Monitoreo y Evaluación | G4: P1.3 | H4: Reuniones de retroalimentación
A5: R3 | B5: Los procesos priorizados de recaudación del impuesto predial en los Gobiernos Locales son más eficaces y eficientes | D5: D1.4 | E5: Coordinación con socios, cooperantes y Programas de SECO | G5: P2.1 | H5: Cursos
A6: R4 | B6: El control interno y la integridad pública del GSN se fortalecen | D6: D1.5 | E6: Evaluación de los GSN | G6: P2.2 | H6: Diplomado
A7: R5 | B7: La capacidad de los operadores de justicia para recuperar activos ilícitos se consolida | D7: D1.6 | E7: Gestión del Conocimiento y Sostenibilidad | G7: P2.3 | H7: Capacitación ad hoc
A8: CB | B8: Conservación de la Biodiversidad y Lucha contra el Cambio Climático | D8: P1 | E8: Asistencia técnica | G8: P2.4 | H8: Programa de entrenamiento
D9: P2 | E9: Fortalecimiento de capacidades | G9: P2.5 | H9: Charla
D10: P3 | E10: Instrumentos de mejora de la gestión | G10: P3.4 | H10: Propuesta de modificación técnico-administrativa a nivel institucional
D11: P4 | E11: Tecnologia de la Informacion / Instrumentos de innovación | G11: P3.5 | H11: Propuesta de modificación técnico-administrativa a nivel sectorial
D12: P5 | E12: Instrumentos de Gestión del Conocimiento (Publicaciones) | G12: P4.1 | H12: Estrategia para la eficiencia de procesos
D13: P6 | G13: P4.2 | H13: Intervención costo-efectivaaa
G14: P5.1 | H14: Documentos de trabajo
G15: P5.2 | H15: Documentos de buenas prácticas y lecciones aprendidas
G16: P5.3 | H16: Documentos de política

Sheet Consultores
A1: Consultor | B1: Tipo | C1: Usuario | D1: Password | E1: Tipo consultor | F1: Área de Especialidad | G1: Entidad | H1: Resultado | I1: Componente | J1: Teléfono | K1: Correo electrónico | L1: Correo personal
A2: Admin | B2: admin | C2: admin | D2: admin1234 | E2: Dirección | F2: Dirección | G2: Todo el ámbito del Programa | H2: D,R,C
A3: Jorge Manrique | B3: user | C3: jorge.manrique | D3: jorge.manrique8724 | E3: Itinerante | F3: Conservación de Biodiversidad | G3: Todo el ámbito del Programa | H3: CB | I3: Gestión de las Finanzas Públicas | K3: jorge.manrique@gfpsubnacional.pe
A4: Gustavo Martin | B4: user | C4: gustavo.martin | D4: gustavo.martin.4532 | E4: Itinerante | F4: Conservación de Biodiversidad | G4: Todo el ámbito del Programa | H4: D1, CB | I4: Gestión de las Finanzas Públicas | K4: gustavo.martin@gfpsubnacional.pe
A5: Luz Garrido | B5: user | C5: lgarrido | D5: lgarrido6715 | E5: Itinerante | F5: Contrataciones | G5: Todo el ámbito del Programa | H5: R1 | I5: Gestión de las Finanzas Públicas | J5: 986723737 / 997025160 | K5: lgarrido@gfpsubnacional.pe | L5: lmgarridop@hotmail.com
A6: Eduardo Padilla | B6: user | C6: rodolfo.padilla | D6: rodolfo.padilla3100 | E6: Itinerante | F6: Inversiones | G6: Todo el ámbito del Programa | H6: R2 | I6: Gestión de las Finanzas Públicas | J6: 980449097 | K6: rodolfo.padilla@gfpsubnacional.pe | L6: eduardopadillac@hotmail.com
A7: Luis Liñán | B7: user | C7: luis.linan | D7: luis.linan8464 | E7: Itinerante | F7: Rentas | G7: Todo el ámbito del Programa | H7: R3 | I7: Gestión de las Finanzas Públicas | J7: 922756652 | K7: luis.linan@gfpsubnacional.pe | L7: eduardo_lb_2004@hotmail.com
A8: Aldo Bautista | B8: user | C8: aldo.bautista | D8: aldo.bautista5368 | E8: Itinerante | F8: Integridad y Riesgos | G8: Todo el ámbito del Programa | H8: R4 | I8: Integridad Pública | J8: 954693246 | K8: aldo.bautista@gfpsubnacional.pe
A9: Verónica Ferreyra | B9: user | C9: veronica.ferreyra | D9: veronica.ferreyra3140 | E9: Consultora | F9: Recuperación de activos | G9: Fiscalía y Poder Judicial | H9: R5 | I9: Recuperación de Activos | K9: veronica.ferreyra@gfpsubnacional.pe
A10: Sergio Jimenez | B10: user | C10: sergio.jimenez | D10: sergio.jimenez9375 | E10: Itinerante | H10: R5 | K10: sergio.jimenez@baselgovernance.org
A11: Limberg Chero | B11: user | C11: lchero | D11: lchero6776 | E11: Itinerante | F11: Coordinación institucional | G11: Todo el ámbito del Programa | H11: D1.4 | I11: Coordinación Institucional | K11: lchero@gfpsubnacional.pe
A12: Jorge Rodas | B12: user | C12: jorge.rodas | D12: jorge.rodas8451 | E12: Itinerante | F12: Publicaciones | G12: Todo el ámbito del Programa | H12: D1.6 | I12: Gestión del Conocimiento | K12: jorge.rodas@gfpsubnacional.pe
A13: Yois Avila | B13: user | C13: yois.avila | D13: yois.avila4984 | E13: Residente | F13: Rentas | G13: MPP | H13: R3 | I13: Gestión de las Finanzas Públicas | J13: 940 530 377 | K13: yois.avila@gfpsubnacional.pe
A14: Nelson Baez | B14: user | C14: nelson.baez | D14: nelson.baez2073 | E14: Residente | F14: Inversiones | G14: GORE Cusco/MP Cusco | H14: R2 | I14: Gestión de las Finanzas Públicas | J14: 980636629 | K14: nelson.baez@gfpsubnacional.pe | L14: nelsonbaezpacheco@hotmail.com
A15: Carla Berrios | B15: user | C15: carla.berrios | D15: carla.berrios6713 | E15: Residente | F15: Inversiones | G15: GORE Apurímac/MP Abancay | H15: R2 | I15: Gestión de las Finanzas Públicas | J15: 953911888 | K15: carla.berrios@gfpsubnacional.pe | L15: caberrios@gmail.com
A16: Constante Castillo | B16: user | C16: constante.castillo | D16: constante.castillo1331 | E16: Residente | F16: Inversiones | G16: GORE La Libertad/MP de Trujillo | H16: R2 | I16: Gestión de las Finanzas Públicas | J16: 949910756 | K16: constante.castillo@gfpsubnacional.pe | L16: castilloalva@gmail.com
A17: Diana Castro | B17: user | C17: diana.castro | D17: diana.castro5478 | E17: Residente | F17: Inversiones | G17: GORE Piura | H17: R2 | I17: Gestión de las Finanzas Públicas | J17: 965195777 | K17: diana.castro@gfpsubnacional.pe | L17: diancas_08@hotmail.com
A18: Xiomara Carbajal | B18: user | C18: xcarbajal | D18: xcarbajal8653 | E18: Residente | F18: Contrataciones | G18: GORE Apurímac/MP Abancay | H18: R1 | I18: Gestión de las Finanzas Públicas | J18: 989244539 | K18: xcarbajal@gfpsubnacional.pe | L18: xiomy_pezo@hotmail.com
A19: Martín Cayo | B19: user | C19: martin.cayo | D19: martin.cayo6025 | E19: Residente | F19: Contrataciones | G19: GORE Cusco/MP Cusco | H19: R1 | I19: Gestión de las Finanzas Públicas | K19: martin.cayo@gfpsubnacional.pe
A20: Delia Contreras | B20: user | C20: delia.contreras | D20: delia.contreras4759 | E20: Residente | F20: Rentas | G20: MPA, MPC | H20: R3 | I20: Gestión de las Finanzas Públicas | K20: delia.contreras@gfpsubnacional.pe
A21: Elva Cruz | B21: user | C21: elva.cruz | D21: elva.cruz6246 | E21: Residente | F21: Inversiones | G21: GORE San Martín/MP San Martin | H21: R2 | I21: Gestión de las Finanzas Públicas | J21: 945047558 | K21: elva.cruz@gfpsubnacional.pe | L21: ecruz281@hotmail.com
A22: Milagrito Diaz | B22: user | C22: milagrito.diaz | D22: milagrito.diaz9265 | E22: Residente | F22: Contrataciones | G22: GORE La Libertad/MP de Trujillo | H22: R1 | I22: Gestión de las Finanzas Públicas | J22: 914819913 | K22: milagrito.diaz@gfpsubnacional.pe | L22: mdiaz2810@yahoo.es
A23: Dalila Diaz | B23: user | C23: dalila.diaz | D23: dalila.diaz1190 | E23: Residente | F23: Contrataciones | G23: GORE San Martín/MP San Martin | H23: R1 | I23: Gestión de las Finanzas Públicas | J23: 952689761 | K23: dalila.diaz@gfpsubnacional.pe | L23: diazurcia@gmail.com
A24: Michael Ludeña | B24: user | C24: luis.ludena | D24: luis.ludena2617 | E24: Residente | F24: Rentas | G24: MPSM | H24: R3 | I24: Gestión de las Finanzas Públicas | J24: 949411116 | K24: luis.ludena@gfpsubnacional.pe
A25: Julio Morales | B25: user | C25: julio.morales | D25: julio.morales2846 | E25: Residente | F25: Inversiones | G25: GORE Lambayeque | H25: R2 | I25: Gestión de las Finanzas Públicas | K25: julio.morales@gfpsubnacional.pe
A26: Lisseth Galiano | B26: user | C26: lisseth.galiano | D26: lisseth.galiano6607 | E26: Itinerante | F26: Integridad y Riesgos | G26: Todo el ámbito del Programa | H26: R4 | I26: Integridad Pública | K26: lisseth.galiano@gfpsubnacional.pe
A27: Jorge Rojas | B27: user | C27: jrojas | D27: jrojas1529 | E27: Residente | F27: Contrataciones | G27: GORE Lambayeque | H27: R1 | I27: Gestión de las Finanzas Públicas | J27: 981800598 | K27: jrojas@gfpsubnacional.pe | L27: jorchst@gmail.com
A28: Lady Seminario | B28: user | C28: lseminario | D28: lseminario8059 | E28: Residente | F28: Contrataciones | G28: GORE Piura | H28: R1 | I28: Gestión de las Finanzas Públicas | J28: 986723762 / 975459691 | K28: lseminario@gfpsubnacional.pe | L28: semibeni@hotmail.com
A29: Luis Yzquierdo | B29: user | C29: luis.yzquierdo | D29: luis.yzquierdo1647 | E29: Residente | F29: Rentas | G29: MPT | H29: R3 | I29: Gestión de las Finanzas Públicas | K29: luis.yzquierdo@gfpsubnacional.pe
A30: Eduardo Morales | B30: user | C30: eduardo.morales | D30: eduardo.morales6128 | E30: Residente | F30: Conservación de Biodiversidad | G30: GORE Loreto | H30: CB | I30: Gestión de las Finanzas Públicas | K30: eduardo.morales@gfpsubnacional.pe
A31: Felipe Lopez | B31: user | C31: felipe.lopez | D31: felipe.lopez2025 | E31: Residente | F31: Conservación de Biodiversidad | G31: GORE Loreto | H31: CB | I31: Gestión de las Finanzas Públicas | K31: felipe.lopez@gfpsubnacional.pe
A32: Mariana León | B32: user | C32: mariana.leon | D32: mariana.leon5123 | E32: Residente | F32: Conservación de Biodiversidad | G32: GORE San Martín | H32: CB | I32: Gestión de las Finanzas Públicas | K32: mariana.leon@gfpsubnacional.pe
A33: Estrella Medina | B33: user | C33: estrella.medina | D33: estrella.medina2277 | E33: Residente | F33: Conservación de Biodiversidad | G33: GORE San Martín | H33: CB | I33: Gestión de las Finanzas Públicas | K33: estrella.medina@gfpsubnacional.pe
A34: Judith Hernández | B34: user | C34: judith.hernandez | D34: judith.hernandez7103 | E34: Residente | F34: Conservación de Biodiversidad | G34: GORE Cusco | H34: CB | I34: Gestión de las Finanzas Públicas | K34: judith.hernandez@gfpsubnacional.pe
A35: Luis Gallegos | B35: user | C35: luis.gallegos | D35: luis.gallegos9041 | E35: Residente | F35: Conservación de Biodiversidad | G35: GORE Cusco | H35: CB | I35: Gestión de las Finanzas Públicas | K35: luis.gallegos@gfpsubnacional.pe
A36: Usuario de Prueba | B36: user | C36: prueba | D36: prueba | E36: Itinerante | F36: Rentas | G36: Todo el ámbito del Programa | H36: R3 | I36: Gestión de las Finanzas Públicas | J36: 922756652 | K36: prueba@gfpsubnacional.pe | L36: prueba@hotmail.com

Sheet varios
A1: nombre | B1: opcion1 | C1: opcion2 | D1: opcion3 | E1: opcion4 | F1: opcion5 | G1: opcion6 | H1: opcion7 | I1: opcion8 | J1: opcion9 | K1: opcion10 | L1: opcion11 | M1: opcion12 | N1: opcion13 | O1: opcion14 | P1: opcion15 | Q1: opcion16 | R1: opcion17 | S1: opcion18 | T1: opcion19 | U1: opcion20 | V1: opcion21 | W1: opcion22 | X1: opcion23 | Y1: opcion24 | Z1: opcion25 | AA1: opcion26 | AB1: opcion27 | AC1: opcion28 | AD1: opcion29 | AE1: opcion30 | AF1: opcion31
A2: etapa | B2: Meta concluída | C2: Meta en proceso
A3: ambitos | B3: Ninguna | C3: Nacional | D3: Todas las regiones | E3: Todas las provincias | F3: Región Apurímac | G3: Región Cusco | H3: Región Lambayeque | I3: Región La Libertad | J3: Región Loreto | K3: Región Piura | L3: Región San Martin | M3: Provincia Abancay | N3: Provincia Cusco | O3: Provincia Maynas | P3: Provincia Trujillo | Q3: Provincia Piura | R3: Provincia San Martin
A4: entidades | B4: Ninguna | C4: Todos los GL | D4: Todos los GR | E4: Todos los GSN | F4: GRA | G4: GRC | H4: GRL | I4: GRLL | J4: GRLO | K4: GRP | L4: GRSM | M4: MPA | N4: MPC | O4: MPM | P4: MPT | Q4: MPP | R4: MPSM | S4: Fiscalía | T4: Poder Judicial | U4: Procuraduría General del Estado | V4: Presidencia del Consejo de Ministros | W4: Contraloría General de la República | X4: Ministerio de Economía y Finanzas | Y4: Ministerio de Vivienda | Z4: Ministerio de Salud | AA4: Ministerio de Educación | AB4: ENAP | AC4: SERFOR | AD4: SERNANP | AE4: OSINFOR
